<mujoco model="pineapple">
  <compiler angle="radian" meshdir="meshes"/>

  <default>
      <default class="pinapple">
          <geom friction="0.4" margin="0.001" condim="1"/>
          <joint damping="0.1" armature="0.01" frictionloss="0.2"/>
          <motor ctrlrange="-23.7 23.7"/>
          <default class="l_hip">
              <joint axis="1 0 0" range="-0.52358 0.17444"/>
              <motor ctrlrange="-23.7 23.7"/>
          </default>
          <default class="r_hip">
              <joint axis="1 0 0" range="-0.17444 0.52358"/>
              <motor ctrlrange="-23.7 23.7"/>
          </default>
          <default class="thigh">
              <joint axis="0 1 0" range="0 1.57"/>
              <motor ctrlrange="-23.7 23.7"/>
          </default>
          <default class="calf">
              <joint axis="0 1 0" range="-3.141 0"/>
              <motor ctrlrange="-33.5 33.5"/>
          </default>
          <default class="visual">
              <geom type="mesh" contype="0" conaffinity="0" group="2"/>
          </default>
          <default class="collision">
              <geom group="3" type="mesh" rgba="1 0 0 0.3" />
              <default class="wheel">
              <geom size="0.022" priority="1" condim="6"
                  friction="0.8 0.02 0.01"/>
              </default>
          </default>
      </default>
  </default>

  <asset>
    <mesh name="base_link" file="base_link.STL"/>
    <mesh name="base_link_collision" file="base_link_collision.STL"/>
    <mesh name="cam" file="cam.STL"/>
    <mesh name="L_hip" file="L_hip.STL"/>
    <mesh name="L_thigh" file="L_thigh.STL"/>
    <mesh name="L_thigh_collision" file="L_thigh_collision.STL"/>
    <mesh name="L_calf" file="L_calf.STL"/>
    <mesh name="L_calf_collision" file="L_calf_collision.STL"/>
    <mesh name="L_wheel" file="L_wheel.STL"/>
    <mesh name="R_hip" file="R_hip.STL"/>
    <mesh name="R_thigh" file="R_thigh.STL"/>
    <mesh name="R_thigh_collision" file="R_thigh_collision.STL"/>
    <mesh name="R_calf" file="R_calf.STL"/>
    <mesh name="R_calf_collision" file="R_calf_collision.STL"/>
    <mesh name="R_wheel" file="R_wheel.STL"/>
  </asset>

  <worldbody>
  <body name="base_link" pos="0 0 0.5" childclass="pinapple">
      <inertial pos="-0.02063232 0.00164283 -0.01555938" quat="1 0 0 0" mass="2.65" diaginertia="0.01804185 0.01102779 0.00752637" />
      <freejoint />
      <site name="imu" pos="0 0 0" />
      <geom type="mesh" contype="0" conaffinity="0" group="1" density="0" rgba="0.278431 0.278431 0.278431 1" mesh="base_link"/>
      <geom type="mesh" rgba="0.752941 0.752941 0.752941 1" mesh="base_link_collision" class="collision"/>
      <geom pos="0.136663 0 0.0595399" quat="0.939693 0 0.34202 0" type="mesh" contype="0" conaffinity="0" group="1" density="0" rgba="0 1 0 1" mesh="cam"/>
      <body name="L_hip" pos="0 0.06125 0" >
        <inertial pos="0.00220652 -0.0027574 0" quat="0.495134 0.500357 0.505071 0.499388" mass="0.573" diaginertia="0.000929348 0.00066652 0.000585923"/>
        <joint name="L_hip_joint" class="l_hip"/>
        <geom type="mesh" contype="0" conaffinity="0" group="1" density="0" rgba="0.278431 0.278431 0.278431 1" mesh="L_hip"/>
        <body name="L_thigh" pos="0 0.0129353 0">
          <inertial pos="-3.299e-05 0.0244218 -0.117735" quat="0.707036 0.023514 -0.0231203 0.706408" mass="0.75" diaginertia="0.00564047 0.00538335 0.000562767"/>
          <joint name="L_thigh_joint" class="thigh"/>
          <geom type="mesh" contype="0" conaffinity="0" group="1" density="0" rgba="0.278431 0.278431 0.278431 1" mesh="L_thigh"/>
          <geom type="mesh" rgba="0.752941 0.752941 0.752941 1" mesh="L_thigh_collision" class="collision"/>
          <body name="L_calf" pos="0 0.0359318 -0.19">
            <inertial pos="-6.699e-05 0.0320149 -0.120893" quat="0.705593 -0.00113069 0.00081195 0.708616" mass="0.5" diaginertia="0.00347573 0.0034163 0.000198615"/>
            <joint name="L_calf_joint" class="calf"/>
            <geom type="mesh" contype="0" conaffinity="0" group="1" density="0" rgba="0.278431 0.278431 0.278431 1" mesh="L_calf"/>
            <geom type="mesh" rgba="0.752941 0.752941 0.752941 1" mesh="L_calf_collision" class="collision"/>
            <body name="L_wheel" pos="0 0.0421818 -0.19">
              <inertial pos="0 0.0125028 0" quat="0.642727 0.294626 0.294808 0.642795" mass="0.305" diaginertia="0.00105427 0.000539886 0.000539684"/>
              <joint name="L_wheel_joint" pos="0 0 0" axis="0 1 0" actuatorfrcrange="-3.69 3.69"/>
              <geom type="mesh" contype="0" conaffinity="0" group="1" density="0" rgba="0.792157 0.819608 0.933333 1" mesh="L_wheel"/>
              <geom size="0.075 0.013" pos="0 0.013 0" quat="0.707105 0.707108 0 0" type="cylinder" rgba="0.792157 0.819608 0.933333 1" class="collision"/>
            </body>
          </body>
        </body>
      </body>
      <body name="R_hip" pos="0 -0.06125 0">
        <inertial pos="0.00220657 0.00275734 0" quat="0.499604 0.504856 0.500523 0.494968" mass="0.573" diaginertia="0.000929348 0.000666519 0.000585923"/>
        <joint name="R_hip_joint" class="r_hip"/>
        <geom type="mesh" contype="0" conaffinity="0" group="1" density="0" rgba="0.278431 0.278431 0.278431 1" mesh="R_hip"/>
        <body name="R_thigh" pos="0 -0.0129353 0">
          <inertial pos="-3.518e-05 -0.024423 -0.117737" quat="0.706424 -0.0231082 0.0235272 0.70702" mass="0.75" diaginertia="0.00563942 0.00538265 0.000562439"/>
          <joint name="R_thigh_joint" class="thigh"/>
          <geom type="mesh" contype="0" conaffinity="0" group="1" density="0" rgba="0.278431 0.278431 0.278431 1" mesh="R_thigh"/>
          <geom type="mesh" rgba="0.278431 0.278431 0.278431 1" mesh="R_thigh_collision" class="collision"/>
          <body name="R_calf" pos="0 -0.0359318 -0.19">
            <inertial pos="-6.785e-05 -0.0320155 -0.120892" quat="0.708616 0.000810906 -0.00112966 0.705593" mass="0.5" diaginertia="0.00347557 0.00341614 0.000198605"/>
            <joint name="R_calf_joint" class="calf"/>
            <geom type="mesh" contype="0" conaffinity="0" group="1" density="0" rgba="0.278431 0.278431 0.278431 1" mesh="R_calf"/>
            <geom type="mesh" rgba="0.278431 0.278431 0.278431 1" mesh="R_calf_collision" class="collision"/>
            <body name="R_wheel" pos="0 -0.0421818 -0.19">
              <inertial pos="0 -0.0125028 0" quat="0.297382 0.641457 0.641639 0.297315" mass="0.305" diaginertia="0.00105426 0.000539805 0.000539745"/>
              <joint name="R_wheel_joint" pos="0 0 0" axis="0 1 0" actuatorfrcrange="-3.69 3.69"/>
              <geom type="mesh" contype="0" conaffinity="0" group="1" density="0" rgba="0.792157 0.819608 0.933333 1" mesh="R_wheel"/>
              <geom size="0.075 0.013" pos="0 -0.013 0" quat="0.707105 0.707108 0 0" type="cylinder" rgba="0.792157 0.819608 0.933333 1" class="collision"/>
            </body>
          </body>
        </body>
      </body>
    </body>
  </worldbody>

  <actuator>
      <motor class="l_hip" name="L_hip" joint="L_hip_joint" />
      <motor class="thigh" name="L_thigh" joint="L_thigh_joint" />
      <motor class="calf" name="L_calf" joint="L_calf_joint" />
      <motor ctrlrange="-3.69 3.69" name="L_wheel" joint="L_wheel_joint" />

      <motor class="r_hip" name="R_hip" joint="R_hip_joint" />
      <motor class="thigh" name="R_thigh" joint="R_thigh_joint" />
      <motor class="calf" name="R_calf" joint="R_calf_joint" />
      <motor ctrlrange="-3.69 3.69" name="R_wheel" joint="R_wheel_joint" />

  </actuator>

  <sensor>

      <jointpos name="L_hip_pos" joint="L_hip_joint" />
      <jointpos name="L_thigh_pos" joint="L_thigh_joint" />
      <jointpos name="L_calf_pos" joint="L_calf_joint" />
      <jointpos name="L_wheel_pos" joint="L_wheel_joint" />

      <jointpos name="R_hip_pos" joint="R_hip_joint" />
      <jointpos name="R_thigh_pos" joint="R_thigh_joint" />
      <jointpos name="R_calf_pos" joint="R_calf_joint" />
      <jointpos name="R_wheel_pos" joint="R_wheel_joint" />

      <jointvel name="L_hip_vel" joint="L_hip_joint" />
      <jointvel name="L_thigh_vel" joint="L_thigh_joint" />
      <jointvel name="L_calf_vel" joint="L_calf_joint" />
      <jointvel name="L_wheel_vel" joint="L_wheel_joint" noise="0.0"/>

      <jointvel name="R_hip_vel" joint="R_hip_joint" />
      <jointvel name="R_thigh_vel" joint="R_thigh_joint" />
      <jointvel name="R_calf_vel" joint="R_calf_joint" />
      <jointvel name="R_wheel_vel" joint="R_wheel_joint" noise="0.0"/>

      <jointactuatorfrc name="L_hip_torque" joint="L_hip_joint" noise="0.01" />
      <jointactuatorfrc name="L_thigh_torque" joint="L_thigh_joint" noise="0.01" />
      <jointactuatorfrc name="L_calf_torque" joint="L_calf_joint" noise="0.01" />
      <jointactuatorfrc name="L_wheel_torque" joint="L_wheel_joint" />

      <jointactuatorfrc name="R_hip_torque" joint="R_hip_joint" noise="0.01" />
      <jointactuatorfrc name="R_thigh_torque" joint="R_thigh_joint" noise="0.01" />
      <jointactuatorfrc name="R_calf_torque" joint="R_calf_joint" noise="0.01" />
      <jointactuatorfrc name="R_wheel_torque" joint="R_wheel_joint" />


      <framequat name="imu_quat" objtype="site" objname="imu" noise="0.0"/>
      <gyro name="imu_gyro" site="imu" noise="0.0"/>
      <accelerometer name="imu_acc" site="imu" />

      <framepos name="frame_pos" objtype="site" objname="imu" />
      <framelinvel name="frame_lin_vel" objtype="site" objname="imu" />
      <frameangvel name="frame_ang_vel" objtype="site" objname="imu" />
  </sensor>
</mujoco>
