<mujoco model="pineapple">
  <compiler angle="radian" meshdir="../meshes/"/>

  <default>
      <default class="pinapple">
          <geom friction="0.4" margin="0.001" condim="1"/>
          <joint damping="0.1" armature="0.01" frictionloss="0.2"/>
          <motor ctrlrange="-23.7 23.7"/>
          <default class="hip">
              <joint axis="1 0 0" range="0 1.57"/>
              <motor ctrlrange="-23.7 23.7"/>
          </default>
          <default class="thigh">
              <joint axis="0 1 0" range="0 2.1"/>
              <motor ctrlrange="-23.7 23.7"/>
          </default>
          <default class="calf">
              <joint axis="0 1 0" range="-3.3 0"/>
              <motor ctrlrange="-23.7 23.7"/>
          </default>
          <default class="visual">
              <geom type="mesh" contype="0" conaffinity="0" group="2"/>
          </default>
          <default class="collision">
              <geom group="3" type="mesh" rgba="1 0 0 0.3" />
              <default class="wheel">
              <geom size="0.022" priority="1" condim="6"
                  friction="0.8 0.02 0.01"/>
              </default>
          </default>
      </default>
  </default>

  <asset>
    <mesh name="base_link" file="base_link.STL"/>
    <mesh name="base_collision" file="base_collision.STL"/>
    <mesh name="L_hip" file="L_hip.STL"/>
    <mesh name="L_thigh" file="L_thigh.STL"/>
    <mesh name="L_thigh_collision" file="L_thigh_collision.STL"/>
    <mesh name="L_calf" file="L_calf.STL"/>
    <mesh name="L_calf_collision" file="L_calf_collision.STL"/>
    <mesh name="L_wheel" file="L_wheel.STL"/>
    <mesh name="R_hip" file="R_hip.STL"/>
    <mesh name="R_thigh" file="R_thigh.STL"/>
    <mesh name="R_thigh_collision" file="R_thigh_collision.STL"/>
    <mesh name="R_calf" file="R_calf.STL"/>
    <mesh name="R_calf_collision" file="R_calf_collision.STL"/>
    <mesh name="R_wheel" file="R_wheel.STL"/>
  </asset>

  <worldbody>
    <body name="base_link" pos="0 0 0.5" childclass="pinapple">
      <inertial pos="0.00129425 0.00000000 0.01223901" quat="1 0 0 0" mass="2.65" diaginertia="0.010702 0.010715 0.014614" />
      <freejoint />
      <site name="imu" pos="0 0 0" />
      <geom type="mesh" contype="0" conaffinity="0" group="1" density="0" rgba="0.752941 0.752941 0.752941 1" mesh="base_link"/>
      <geom type="mesh" rgba="0.752941 0.752941 0.752941 1" mesh="base_collision" class="collision"/>
      <body name="L_hip" pos="0 0.06125 0.0610009">
        <inertial pos="0.00055289 -0.0027574 0" quat="0.494955 0.500535 0.504889 0.499571" mass="0.64" diaginertia="0.00103802 0.000744461 0.000654438"/>
        <joint name="L_hip_joint" class="hip"/>
        <geom type="mesh" contype="0" conaffinity="0" group="1" density="0" rgba="0.278431 0.278431 0.278431 1" mesh="L_hip"/>
        <body name="L_thigh" pos="0 0.01 0">
          <inertial pos="-0.00168662 0.0273571 -0.117736" quat="0.707037 0.0235137 -0.0231196 0.706408" mass="0.88" diaginertia="0.00661815 0.00631647 0.000660314"/>
          <joint name="L_thigh_joint" class="thigh"/>
          <geom type="mesh" contype="0" conaffinity="0" group="1" density="0" rgba="0.752941 0.752941 0.752941 1" mesh="L_thigh"/>
          <geom type="mesh" rgba="0.752941 0.752941 0.752941 1" mesh="L_thigh_collision" class="collision"/>
          <body name="L_calf" pos="-0.00165363 0.0388671 -0.190001">
            <inertial pos="-6.699e-05 0.0320149 -0.120893" quat="0.70557 -0.00113142 0.000811229 0.708639" mass="0.65" diaginertia="0.00451844 0.00444119 0.000258197"/>
            <joint name="L_calf_joint" class="calf"/>
            <geom type="mesh" contype="0" conaffinity="0" group="1" density="0" rgba="0.752941 0.752941 0.752941 1" mesh="L_calf"/>
            <geom type="mesh" rgba="0.752941 0.752941 0.752941 1" mesh="L_calf_collision" class="collision"/>
            <body name="L_wheel" pos="0 0.0421818 -0.19">
              <inertial pos="0 0.0125028 0" quat="0.421371 0.567852 0.567833 0.421374" mass="0.305" diaginertia="0.00105427 0.000539803 0.000539767"/>
              <joint name="L_wheel_joint" pos="0 0 0" axis="0 1 0" actuatorfrcrange="-3.69 3.69"/>
              <geom type="mesh" contype="0" conaffinity="0" group="1" density="0" rgba="0.792157 0.819608 0.933333 1" mesh="L_wheel"/>
              <geom size="0.075 0.013" pos="0 0.013 0" quat="0.707105 0.707108 0 0" type="cylinder" rgba="0.792157 0.819608 0.933333 1" class="wheel"/>
            </body>
          </body>
        </body>
      </body>
      <body name="R_hip" pos="0 -0.06125 0.0610009">
        <inertial pos="0.00055295 0.00275734 0" quat="0.49948 0.504979 0.500438 0.495052" mass="0.64" diaginertia="0.00103801 0.000744451 0.000654428"/>
        <joint name="R_hip_joint" pos="0 0 0" axis="1 0 0"/>
        <geom type="mesh" contype="0" conaffinity="0" group="1" density="0" rgba="0.278431 0.278431 0.278431 1" mesh="R_hip"/>
        <body name="R_thigh" pos="0.01 0 0">
          <inertial pos="-0.0116884 -0.037357 -0.117738" quat="0.706435 -0.0231085 0.0235257 0.70701" mass="0.88" diaginertia="0.00661765 0.00631637 0.000659923"/>
          <joint name="R_thigh_joint" pos="0 0 0" axis="0 1 0" range="0 2.1" actuatorfrcrange="-23.7 23.7"/>
          <geom type="mesh" contype="0" conaffinity="0" group="1" density="0" rgba="0.752941 0.752941 0.752941 1" mesh="R_thigh"/>
          <geom type="mesh" rgba="0.752941 0.752941 0.752941 1" mesh="R_thigh_collision" class="collision"/>
          <body name="R_calf" pos="-0.0116536 -0.0488671 -0.190001">
            <inertial pos="8.556e-05 -0.0323822 -0.120893" quat="0.706888 -0.000592015 -0.000499787 0.707325" mass="0.65" diaginertia="0.00451844 0.00444119 0.000258197"/>
            <joint name="R_calf_joint" pos="0 0 0" axis="0 1 0" range="-3.3 0" actuatorfrcrange="-23.7 23.7"/>
            <geom type="mesh" contype="0" conaffinity="0" group="1" density="0" rgba="0.752941 0.752941 0.752941 1" mesh="R_calf"/>
            <geom type="mesh" rgba="0.752941 0.752941 0.752941 1" mesh="R_calf_collision" class="collision"/>
            <body name="R_wheel" pos="0 -0.0421818 -0.19">
              <inertial pos="0 -0.0125028 0" quat="0.297335 0.641547 0.641565 0.297329" mass="0.305" diaginertia="0.00105426 0.000539805 0.000539745"/>
              <joint name="R_wheel_joint" pos="0 0 0" axis="0 1 0" actuatorfrcrange="-3.69 3.69"/>
              <geom type="mesh" contype="0" conaffinity="0" group="1" density="0" rgba="0.792157 0.819608 0.933333 1" mesh="R_wheel"/>
              <geom size="0.075 0.013" pos="0 -0.013 0" quat="0.707105 0.707108 0 0" type="cylinder" rgba="0.792157 0.819608 0.933333 1" class="wheel"/>
            </body>
          </body>
        </body>
      </body>
    </body>  
  </worldbody>

  <actuator>
      <motor class="hip" name="L_hip" joint="L_hip_joint" />
      <motor class="thigh" name="L_thigh" joint="L_thigh_joint" />
      <motor class="calf" name="L_calf" joint="L_calf_joint" />
      <motor ctrlrange="-15 15" name="L_wheel" joint="L_wheel_joint" />

      <motor class="hip" name="R_hip" joint="R_hip_joint" />
      <motor class="thigh" name="R_thigh" joint="R_thigh_joint" />
      <motor class="calf" name="R_calf" joint="R_calf_joint" />
      <motor ctrlrange="-15 15" name="R_wheel" joint="R_wheel_joint" />

  </actuator>

  <sensor>

      <jointpos name="L_hip_pos" joint="L_hip_joint" />
      <jointpos name="L_thigh_pos" joint="L_thigh_joint" />
      <jointpos name="L_calf_pos" joint="L_calf_joint" />
      <jointpos name="L_wheel_pos" joint="L_wheel_joint" />

      <jointpos name="R_hip_pos" joint="R_hip_joint" />
      <jointpos name="R_thigh_pos" joint="R_thigh_joint" />
      <jointpos name="R_calf_pos" joint="R_calf_joint" />
      <jointpos name="R_wheel_pos" joint="R_wheel_joint" />

      <jointvel name="L_hip_vel" joint="L_hip_joint" />
      <jointvel name="L_thigh_vel" joint="L_thigh_joint" />
      <jointvel name="L_calf_vel" joint="L_calf_joint" />
      <jointvel name="L_wheel_vel" joint="L_wheel_joint" noise="0.0"/>

      <jointvel name="R_hip_vel" joint="R_hip_joint" />
      <jointvel name="R_thigh_vel" joint="R_thigh_joint" />
      <jointvel name="R_calf_vel" joint="R_calf_joint" />
      <jointvel name="R_wheel_vel" joint="R_wheel_joint" noise="0.0"/>

      <jointactuatorfrc name="L_hip_torque" joint="L_hip_joint" noise="0.01" />
      <jointactuatorfrc name="L_thigh_torque" joint="L_thigh_joint" noise="0.01" />
      <jointactuatorfrc name="L_calf_torque" joint="L_calf_joint" noise="0.01" />
      <jointactuatorfrc name="L_wheel_torque" joint="L_wheel_joint" />

      <jointactuatorfrc name="R_hip_torque" joint="R_hip_joint" noise="0.01" />
      <jointactuatorfrc name="R_thigh_torque" joint="R_thigh_joint" noise="0.01" />
      <jointactuatorfrc name="R_calf_torque" joint="R_calf_joint" noise="0.01" />
      <jointactuatorfrc name="R_wheel_torque" joint="R_wheel_joint" />


      <framequat name="imu_quat" objtype="site" objname="imu" noise="0.0"/>
      <gyro name="imu_gyro" site="imu" noise="0.0"/>
      <accelerometer name="imu_acc" site="imu" />

      <framepos name="frame_pos" objtype="site" objname="imu" />
      <framelinvel name="frame_lin_vel" objtype="site" objname="imu" />
      <frameangvel name="frame_ang_vel" objtype="site" objname="imu" />
  </sensor>

</mujoco>
