<?xml version="1.0" encoding="utf-8"?>
<!-- This URDF was automatically created by SolidWorks to URDF Exporter! Originally created by Stephen Brawner (brawner@gmail.com) 
     Commit Version: 1.6.0-4-g7f85cfe  Build Version: 1.6.7995.38578
     For more information, please see http://wiki.ros.org/sw_urdf_exporter -->
<robot
  name="pineapple0916">
  <mujoco>
    <compiler
      meshdir="../meshes"
      balanceinertia="true"
      discardvisual="false" />
  </mujoco>
  <link
    name="base_link">
    <inertial>
      <origin
        xyz="-0.02063232 0.00164283 -0.01555938"
        rpy="0 0 0" />
      <mass
        value="2.85000000" />
      <inertia
        ixx="0.01102779"
        ixy="0.00037426"
        ixz="0.00754430"
        iyy="0.01804185"
        iyz="-0.00052496"
        izz="0.00752637" />
    </inertial>
    <visual>
      <origin
        xyz="0 0 0"
        rpy="0 0 0" />
      <geometry>
        <mesh
          filename="package://pineapple0916/meshes/base_link.STL" />
      </geometry>
      <material
        name="">
        <color
          rgba="0.752941176470588 0.752941176470588 0.752941176470588 1" />
      </material>
    </visual>
    <collision>
      <origin
        xyz="0 0 0"
        rpy="0 0 0" />
      <geometry>
        <mesh
          filename="package://pineapple0916/meshes/base_link_collision.STL" />
      </geometry>
    </collision>
  </link>
  <link
    name="cam">
    <inertial>
      <origin
        xyz="0.00000000 0.00000000 0.00000000"
        rpy="0 0 0" />
      <mass
        value="0.30000000" />
      <inertia
        ixx="0.00018085"
        ixy="0.00000269"
        ixz="0.00000005"
        iyy="0.00002720"
        iyz="-0.0000001"
        izz="0.00018280" />
    </inertial>
    <visual>
      <origin
        xyz="0 0 0"
        rpy="0 0 0" />
      <geometry>
        <mesh
          filename="package://pineapple0916/meshes/cam.STL" />
      </geometry>
      <material
        name="">
        <color
          rgba="0 1 0 1" />
      </material>
    </visual>
  </link>
  <joint
    name="cam_joint"
    type="fixed">
    <origin
      xyz="0.136663127592924 0 0.0595399140665773"
      rpy="0 0.698131700797732 0" />
    <parent
      link="base_link" />
    <child
      link="cam" />
    <axis
      xyz="0 0 0" />
  </joint>
  <link
    name="L_hip">
    <inertial>
      <origin
        xyz="0.00220657 -0.00275734 0.00000000"
        rpy="0 0 0" />
      <mass
        value="0.57300000" />
      <inertia
        ixx="0.00058596"
        ixy="-0.00000308"
        ixz="0.00000088"
        iyy="0.00092932"
        iyz="-0.0000001"
        izz="0.00066651" />
    </inertial>
    <visual>
      <origin
        xyz="0 0 0"
        rpy="0 0 0" />
      <geometry>
        <mesh
          filename="package://pineapple0916/meshes/L_hip.STL" />
      </geometry>
      <material
        name="">
        <color
          rgba="0.27843137254902 0.27843137254902 0.27843137254902 1" />
      </material>
    </visual>
  </link>
  <joint
    name="L_hip_joint"
    type="revolute">
    <origin
      xyz="0 0.06125 0"
      rpy="0 0 0" />
    <parent
      link="base_link" />
    <child
      link="L_hip" />
    <axis
      xyz="1 0 0" />
    <limit
      lower="-0.52358"
      upper="0.17444"
      effort="23.7"
      velocity="30.0" />
  </joint>
  <link
    name="L_thigh">
    <inertial>
      <origin
        xyz="-0.00003518 0.02442297 -0.11773718"
        rpy="0 0 0" />
      <mass
        value="0.75000000" />
      <inertia
        ixx="0.00538265"
        ixy="0.00000040"
        ixz="-0.00000270"
        iyy="0.00561736"
        iyz="0.00033393"
        izz="0.00058450" />
    </inertial>
    <visual>
      <origin
        xyz="0 0 0"
        rpy="0 0 0" />
      <geometry>
        <mesh
          filename="package://pineapple0916/meshes/L_thigh.STL" />
      </geometry>
      <material
        name="">
        <color
          rgba="0.752941176470588 0.752941176470588 0.752941176470588 1" />
      </material>
    </visual>
    <collision>
      <origin
        xyz="0 0 0"
        rpy="0 0 0" />
      <geometry>
        <mesh
          filename="package://pineapple0916/meshes/L_thigh_collision.STL" />
      </geometry>
    </collision>
  </link>
  <joint
    name="L_thigh_joint"
    type="revolute">
    <origin
      xyz="0 0.0129353215081658 0"
      rpy="0 0 0" />
    <parent
      link="L_hip" />
    <child
      link="L_thigh" />
    <axis
      xyz="0 1 0" />
    <limit
      lower="0.0"
      upper="1.571"
      effort="23.7"
      velocity="30.0" />
  </joint>
  <link
    name="L_calf">
    <inertial>
      <origin
        xyz="-0.00006785 0.03201549 -0.12089196"
        rpy="0 0 0" />
      <mass
        value="0.50000000" />
      <inertia
        ixx="0.00341614"
        ixy="-0.00000025"
        ixz="0.00000147"
        iyy="0.00347554"
        iyz="-0.00000899"
        izz="0.00019863" />
    </inertial>
    <visual>
      <origin
        xyz="0 0 0"
        rpy="0 0 0" />
      <geometry>
        <mesh
          filename="package://pineapple0916/meshes/L_calf.STL" />
      </geometry>
      <material
        name="">
        <color
          rgba="0.752941176470588 0.752941176470588 0.752941176470588 1" />
      </material>
    </visual>
    <collision>
      <origin
        xyz="0 0 0"
        rpy="0 0 0" />
      <geometry>
        <mesh
          filename="package://pineapple0916/meshes/L_calf_collision.STL" />
      </geometry>
    </collision>
  </link>
  <joint
    name="L_calf_joint"
    type="revolute">
    <origin
      xyz="0 0.035931787557176 -0.190000001217773"
      rpy="0 0 0" />
    <parent
      link="L_thigh" />
    <child
      link="L_calf" />
    <axis
      xyz="0 1 0" />
    <limit
      lower="-3.1416"
      upper="0.0"
      effort="33.5"
      velocity="21.0" />
  </joint>
  <link
    name="L_wheel">
    <inertial>
      <origin
        xyz="0.00000000 0.01250277 0.00000000"
        rpy="0 0 0" />
      <mass
        value="0.30500000" />
      <inertia
        ixx="0.00053977"
        ixy="-0.0000001"
        ixz="0.00000003"
        iyy="0.00105427"
        iyz="-0.0000001"
        izz="0.00053978" />
    </inertial>
    <visual>
      <origin
        xyz="0 0 0"
        rpy="0 0 0" />
      <geometry>
        <mesh
          filename="package://pineapple0916/meshes/L_wheel.STL" />
      </geometry>
      <material
        name="">
        <color
          rgba="0.792156862745098 0.819607843137255 0.933333333333333 1" />
      </material>
    </visual>
    <collision>
        <origin xyz="0 0.013 0" rpy="1.5708 0 0"/>
        <geometry>
          <cylinder radius="0.075" length="0.026"/>
        </geometry>
    </collision>
  </link>
  <joint
    name="L_wheel_joint"
    type="continuous">
    <origin
      xyz="0 0.0421817504179199 -0.190000000000001"
      rpy="0 0 0" />
    <parent
      link="L_calf" />
    <child
      link="L_wheel" />
    <axis
      xyz="0 1 0" />
    <limit
      effort="3.69"
      velocity="60.0" />
  </joint>
  <link
    name="R_hip">
    <inertial>
      <origin
        xyz="0.00220657 0.00275734 0.00000000"
        rpy="0 0 0" />
      <mass
        value="0.57300000" />
      <inertia
        ixx="0.00058596"
        ixy="0.00000308"
        ixz="0.00000087"
        iyy="0.00092932"
        iyz="-0.0000001"
        izz="0.00066651" />
    </inertial>
    <visual>
      <origin
        xyz="0 0 0"
        rpy="0 0 0" />
      <geometry>
        <mesh
          filename="package://pineapple0916/meshes/R_hip.STL" />
      </geometry>
      <material
        name="">
        <color
          rgba="0.27843137254902 0.27843137254902 0.27843137254902 1" />
      </material>
    </visual>
  </link>
  <joint
    name="R_hip_joint"
    type="revolute">
    <origin
      xyz="0 -0.0612499999999985 0"
      rpy="0 0 0" />
    <parent
      link="base_link" />
    <child
      link="R_hip" />
    <axis
      xyz="1 0 0" />
    <limit
      lower="-0.17444"
      upper="0.52358"
      effort="23.7"
      velocity="30.0" />
  </joint>
  <link
    name="R_thigh">
    <inertial>
      <origin
        xyz="-0.00003518 -0.02442297 -0.11773718"
        rpy="0 0 0" />
      <mass
        value="0.75000000" />
      <inertia
        ixx="0.00538265"
        ixy="-0.00000040"
        ixz="-0.00000270"
        iyy="0.00561736"
        iyz="-0.00033393"
        izz="0.00058450" />
    </inertial>
    <visual>
      <origin
        xyz="0 0 0"
        rpy="0 0 0" />
      <geometry>
        <mesh
          filename="package://pineapple0916/meshes/R_thigh.STL" />
      </geometry>
      <material
        name="">
        <color
          rgba="0.27843137254902 0.27843137254902 0.27843137254902 1" />
      </material>
    </visual>
    <collision>
      <origin
        xyz="0 0 0"
        rpy="0 0 0" />
      <geometry>
        <mesh
          filename="package://pineapple0916/meshes/R_thigh_collision.STL" />
      </geometry>
    </collision>
  </link>
  <joint
    name="R_thigh_joint"
    type="revolute">
    <origin
      xyz="0 -0.0129353215081659 0"
      rpy="0 0 0" />
    <parent
      link="R_hip" />
    <child
      link="R_thigh" />
    <axis
      xyz="0 1 0" />
    <limit
      lower="0.0"
      upper="1.571"
      effort="23.7"
      velocity="30.0" />
  </joint>
  <link
    name="R_calf">
    <inertial>
      <origin
        xyz="-0.00006785 -0.03201549 -0.12089196"
        rpy="0 0 0" />
      <mass
        value="0.50000000" />
      <inertia
        ixx="0.00341614"
        ixy="0.00000025"
        ixz="0.00000147"
        iyy="0.00347554"
        iyz="0.00000899"
        izz="0.00019863" />
    </inertial>
    <visual>
      <origin
        xyz="0 0 0"
        rpy="0 0 0" />
      <geometry>
        <mesh
          filename="package://pineapple0916/meshes/R_calf.STL" />
      </geometry>
      <material
        name="">
        <color
          rgba="0.27843137254902 0.27843137254902 0.27843137254902 1" />
      </material>
    </visual>
    <collision>
      <origin
        xyz="0 0 0"
        rpy="0 0 0" />
      <geometry>
        <mesh
          filename="package://pineapple0916/meshes/R_calf_collision.STL" />
      </geometry>
    </collision>
  </link>
  <joint
    name="R_calf_joint"
    type="revolute">
    <origin
      xyz="0 -0.0359317875571787 -0.190000001217773"
      rpy="0 0 0" />
    <parent
      link="R_thigh" />
    <child
      link="R_calf" />
    <axis
      xyz="0 1 0" />
    <limit
      lower="-3.1416"
      upper="0.0"
      effort="33.5"
      velocity="21.0" />
  </joint>
  <link
    name="R_wheel">
    <inertial>
      <origin
        xyz="0.00000000 -0.01250277 0.00000000"
        rpy="0 0 0" />
      <mass
        value="0.30500000" />
      <inertia
        ixx="0.00053977"
        ixy="-0.0000001"
        ixz="0.00000003"
        iyy="0.00105426"
        iyz="-0.0000001"
        izz="0.00053978" />
    </inertial>
    <visual>
      <origin
        xyz="0 0 0"
        rpy="0 0 0" />
      <geometry>
        <mesh
          filename="package://pineapple0916/meshes/R_wheel.STL" />
      </geometry>
      <material
        name="">
        <color
          rgba="0.792156862745098 0.819607843137255 0.933333333333333 1" />
      </material>
    </visual>
    <collision>
      <origin xyz="0 -0.013 0" rpy="1.5708 0 0"/>
      <geometry>
        <cylinder radius="0.075" length="0.026"/>
      </geometry>
    </collision>
  </link>
  <joint
    name="R_wheel_joint"
    type="continuous">
    <origin
      xyz="0 -0.0421817504179163 -0.190000000000001"
      rpy="0 0 0" />
    <parent
      link="R_calf" />
    <child
      link="R_wheel" />
    <axis
      xyz="0 1 0" />
    <limit
      effort="3.69"
      velocity="60.0" />
  </joint>
</robot>