<?xml version="1.0" encoding="utf-8"?>
<!-- This URDF was automatically created by SolidWorks to URDF Exporter! Originally created by Stephen Brawner (brawner@gmail.com) 
     Commit Version: 1.6.0-4-g7f85cfe  Build Version: 1.6.7995.38578
     For more information, please see http://wiki.ros.org/sw_urdf_exporter -->
<robot
  name="pineapple">
  <mujoco>
  <compiler
    meshdir="../meshes"
    balanceinertia="true"
    discardvisual="false" />
  </mujoco>
  <link
    name="base_link">
    <inertial>
      <origin
        xyz="0.00129425 0.00000000 0.01223901"
        rpy="0 0 0" />
      <mass
        value="2.65000000" />
      <inertia
        ixx="0.010715"
        ixy="0.000013"
        ixz="0.000632"
        iyy="0.010702"
        iyz="-0.000011"
        izz="0.014614" />
    </inertial>
    <visual>
      <origin
        xyz="0 0 0"
        rpy="0 0 0" />
      <geometry>
        <mesh
          filename="../meshes/base_link.STL" />
      </geometry>
      <material
        name="">
        <color
          rgba="0.752941176470588 0.752941176470588 0.752941176470588 1" />
      </material>
    </visual>
    <collision>
      <origin
        xyz="0 0 0"
        rpy="0 0 0" />
      <geometry>
        <mesh
          filename="../meshes/base_collision.STL" />
      </geometry>
    </collision>
  </link>
  <link
    name="L_hip">
    <inertial>
      <origin
        xyz="0.00055289 -0.00275740 0.00000000"
        rpy="0 0 0" />
      <mass
        value="0.64000000" />
      <inertia
        ixx="0.00065448"
        ixy="-0.00000344"
        ixz="0.00000098"
        iyy="0.00103799"
        iyz="0.0000001"
        izz="0.00074445" />
    </inertial>
    <visual>
      <origin
        xyz="0 0 0"
        rpy="0 0 0" />
      <geometry>
        <mesh
          filename="../meshes/L_hip.STL" />
      </geometry>
      <material
        name="">
        <color
          rgba="0.27843137254902 0.27843137254902 0.27843137254902 1" />
      </material>
    </visual>
  </link>
  <joint
    name="L_hip_joint"
    type="revolute">
    <origin
      xyz="0 0.061249999999998 0.0610009280869146"
      rpy="0 0 0" />
    <parent
      link="base_link" />
    <child
      link="L_hip" />
    <axis
      xyz="1 0 0" />
  </joint>
  <link
    name="L_thigh">
    <inertial>
      <origin
        xyz="-0.00168662 0.02735711 -0.11773571"
        rpy="0 0 0" />
      <mass
        value="0.88000000" />
      <inertia
        ixx="0.00631647"
        ixy="0.00000047"
        ixz="-0.00000296"
        iyy="0.00659227"
        iyz="0.00039185"
        izz="0.00068620" />
    </inertial>
    <visual>
      <origin
        xyz="0 0 0"
        rpy="0 0 0" />
      <geometry>
        <mesh
          filename="../meshes/L_thigh.STL" />
      </geometry>
      <material
        name="">
        <color
          rgba="0.752941176470588 0.752941176470588 0.752941176470588 1" />
      </material>
    </visual>
    <collision>
      <origin
        xyz="0 0 0"
        rpy="0 0 0" />
      <geometry>
        <mesh
          filename="../meshes/L_thigh_collision.STL" />
      </geometry>
    </collision>
  </link>
  <joint
    name="L_thigh_joint"
    type="revolute">
    <origin
      xyz="0 0.01 0"
      rpy="0 0 0" />
    <parent
      link="L_hip" />
    <child
      link="L_thigh" />
    <axis
      xyz="0 1 0" />
    <limit
      lower="0"
      upper="2.1"
      effort="23.7"
      velocity="30.1" />
  </joint>
  <link
    name="L_calf">
    <inertial>
      <origin
        xyz="-0.00006699 0.03201486 -0.12089345"
        rpy="0 0 0" />
      <mass
        value="0.65000000" />
      <inertia
        ixx="0.00444119"
        ixy="-0.00000033"
        ixz="0.00000192"
        iyy="0.00451841"
        iyz="-0.00001170"
        izz="0.00025823" />
    </inertial>
    <visual>
      <origin
        xyz="0 0 0"
        rpy="0 0 0" />
      <geometry>
        <mesh
          filename="../meshes/L_calf.STL" />
      </geometry>
      <material
        name="">
        <color
          rgba="0.752941176470588 0.752941176470588 0.752941176470588 1" />
      </material>
    </visual>
    <collision>
      <origin
        xyz="0 0 0"
        rpy="0 0 0" />
      <geometry>
        <mesh
          filename="../meshes/L_calf_collision.STL" />
      </geometry>
    </collision>
  </link>
  <joint
    name="L_calf_joint"
    type="revolute">
    <origin
      xyz="-0.0016536285573749 0.0388671106492234 -0.190000930017623"
      rpy="0 0 0" />
    <parent
      link="L_thigh" />
    <child
      link="L_calf" />
    <axis
      xyz="0 1 0" />
    <limit
      lower="-3.3"
      upper="0"
      effort="23.7"
      velocity="30.1" />
  </joint>
  <link
    name="L_wheel">
    <inertial>
      <origin
        xyz="0.00000000 0.01250278 0.00000000"
        rpy="0 0 0" />
      <mass
        value="0.30500000" />
      <inertia
        ixx="0.00053977"
        ixy="0.00000001"
        ixz="0.00000001"
        iyy="0.00105427"
        iyz="0.00000001"
        izz="0.00053980" />
    </inertial>
    <visual>
      <origin
        xyz="0 0 0"
        rpy="0 0 0" />
      <geometry>
        <mesh
          filename="../meshes/L_wheel.STL" />
      </geometry>
      <material
        name="">
        <color
          rgba="0.792156862745098 0.819607843137255 0.933333333333333 1" />
      </material>
    </visual>
    <collision>
        <origin xyz="0 0.013 0" rpy="1.5708 0 0"/>
        <geometry>
          <cylinder radius="0.075" length="0.026"/>
        </geometry>
    </collision>
  </link>
  <joint
    name="L_wheel_joint"
    type="continuous">
    <origin
      xyz="0 0.0421817504179249 -0.190000000000001"
      rpy="0 0 0" />
    <parent
      link="L_calf" />
    <child
      link="L_wheel" />
    <axis
      xyz="0 1 0" />
  </joint>
  <link
    name="R_hip">
    <inertial>
      <origin
        xyz="0.00055295 0.00275734 0.00000000"
        rpy="0 0 0" />
      <mass
        value="0.64000000" />
      <inertia
        ixx="0.00065447"
        ixy="0.00000344"
        ixz="0.00000098"
        iyy="0.00103798"
        iyz="0.00000001"
        izz="0.00074444" />
    </inertial>
    <visual>
      <origin
        xyz="0 0 0"
        rpy="0 0 0" />
      <geometry>
        <mesh
          filename="../meshes/R_hip.STL" />
      </geometry>
      <material
        name="">
        <color
          rgba="0.27843137254902 0.27843137254902 0.27843137254902 1" />
      </material>
    </visual>
  </link>
  <joint
    name="R_hip_joint"
    type="revolute">
    <origin
      xyz="0 -0.0612499999999985 0.0610009280869152"
      rpy="0 0 0" />
    <parent
      link="base_link" />
    <child
      link="R_hip" />
    <axis
      xyz="1 0 0" />
  </joint>
  <link
    name="R_thigh">
    <inertial>
      <origin
        xyz="-0.01168842 -0.03735700 -0.11773770"
        rpy="0 0 0" />
      <mass
        value="0.88000000" />
      <inertia
        ixx="0.00631637"
        ixy="-0.00000046"
        ixz="-0.00000316"
        iyy="0.00659176"
        iyz="-0.00039185"
        izz="0.00068581" />
    </inertial>
    <visual>
      <origin
        xyz="0 0 0"
        rpy="0 0 0" />
      <geometry>
        <mesh
          filename="../meshes/R_thigh.STL" />
      </geometry>
      <material
        name="">
        <color
          rgba="0.752941176470588 0.752941176470588 0.752941176470588 1" />
      </material>
    </visual>
    <collision>
      <origin
        xyz="0 0 0"
        rpy="0 0 0" />
      <geometry>
        <mesh
          filename="../meshes/R_thigh_collision.STL" />
      </geometry>
    </collision>
  </link>
  <joint
    name="R_thigh_joint"
    type="revolute">
    <origin
      xyz="0.01 0 0"
      rpy="0 0 0" />
    <parent
      link="R_hip" />
    <child
      link="R_thigh" />
    <axis
      xyz="0 1 0" />
    <limit
      lower="0"
      upper="2.1"
      effort="23.7"
      velocity="30.1" />
  </joint>
  <link
    name="R_calf">
    <inertial>
      <origin
        xyz="0.00008556 -0.03238223 -0.12089"
        rpy="0 0 0" />
      <mass
        value="0.65000000" />
      <inertia
        ixx="0.00444119"
        ixy="-0.00000033"
        ixz="0.00000192"
        iyy="0.00451841"
        iyz="-0.00001170"
        izz="0.00025823" />
    </inertial>
    <visual>
      <origin
        xyz="0 0 0"
        rpy="0 0 0" />
      <geometry>
        <mesh
          filename="../meshes/R_calf.STL" />
      </geometry>
      <material
        name="">
        <color
          rgba="0.752941176470588 0.752941176470588 0.752941176470588 1" />
      </material>
    </visual>
    <collision>
      <origin
        xyz="0 0 0"
        rpy="0 0 0" />
      <geometry>
        <mesh
          filename="../meshes/R_calf_collision.STL" />
      </geometry>
    </collision>
  </link>
  <joint
    name="R_calf_joint"
    type="revolute">
    <origin
      xyz="-0.0116536285573748 -0.0488671065357543 -0.190000930017624"
      rpy="0 0 0" />
    <parent
      link="R_thigh" />
    <child
      link="R_calf" />
    <axis
      xyz="0 1 0" />
    <limit
      lower="-3.3"
      upper="0"
      effort="23.7"
      velocity="30.1" />
  </joint>
  <link
    name="R_wheel">
    <inertial>
      <origin
        xyz="0.00000000 -0.01250277 0.00000000"
        rpy="0 0 0" />
      <mass
        value="0.30500000" />
      <inertia
        ixx="0.00053977"
        ixy="-0.00000001"
        ixz="0.00000003"
        iyy="0.00105426"
        iyz="-0.00000001"
        izz="0.00053978" />
    </inertial>
    <visual>
      <origin
        xyz="0 0 0"
        rpy="0 0 0" />
      <geometry>
        <mesh
          filename="../meshes/R_wheel.STL" />
      </geometry>
      <material
        name="">
        <color
          rgba="0.792156862745098 0.819607843137255 0.933333333333333 1" />
      </material>
    </visual>
    <collision>
      <origin xyz="0 -0.013 0" rpy="1.5708 0 0"/>
      <geometry>
        <cylinder radius="0.075" length="0.026"/>
      </geometry>
    </collision>
  </link>
  <joint
    name="R_wheel_joint"
    type="continuous">
    <origin
      xyz="0 -0.0421817545313912 -0.190000000000001"
      rpy="0 0 0" />
    <parent
      link="R_calf" />
    <child
      link="R_wheel" />
    <axis
      xyz="0 1 0" />
  </joint>
</robot>